<robot name="joystick">
	<link name="base_link">
		<visual>
			<geometry>
				<box size="0.03 0.03 0.18"/>
			</geometry>
			<origin xyz="0 0 0.09" rpy="0 0 0" />
			<material name="base">
				<color rgba ="1 1 1 1"/>
			</material>
		</visual>
	</link>


	<link name ="pitch_bar_1">
		<visual>
			<geometry>
				<cylinder length="0.13" radius="0.0125"/>
			</geometry>
			<origin xyz="-0.005 0.0 0.0" rpy="1.570796 0 1.570796" />
			<material name="pitch">
				<color rgba="1 0 0 1"/>
			</material>
		</visual>
	</link>


	<link name ="pitch_bar_2">
		<visual>
			<geometry>
				<box size="0.02 0.03 0.1"/>
			</geometry>
			<origin xyz="0 0 -0.035"/>
			<material name="pitch"/>
		</visual>
	</link>
	
	<link name ="pitch_bar_3">
		<visual>
			<geometry>
				<box size="0.12 0.03 0.02"/>
			</geometry>
			<origin xyz="0.05 0 0"/>
			<material name="pitch"/>
		</visual>
	</link>


	<link name ="yaw_bar_1">
		<visual>
			<geometry>
				<cylinder length="0.075" radius="0.0125"/>
			</geometry>
			<origin xyz="0 0 -0.0125"/>
			<material name="yaw">
				<color rgba="0 0 1 1"/>
			</material>
		</visual>
	</link>

	<link name ="yaw_bar_2">
		<visual>
			<geometry>
				<box size="0.075 0.03 0.015"/>
			</geometry>
			<origin xyz="0.0225 0 0"/>
			<material name="yaw"/>
		</visual>
	</link>

	<link name ="yaw_bar_3">
		<visual>
			<geometry>
				<box size="0.02 0.03 0.08"/>
			</geometry>
			<origin xyz="0 0 0.0325"/>
			<material name="yaw"/>
		</visual>
	</link>

	<link name="roll_bar_1">
		<visual>
			<geometry>
				<cylinder length="0.08" radius="0.0125" />
			</geometry>
			<origin xyz="0 0 0" rpy="1.570796 0 1.570796"/>
			<material name="roll">
				<color rgba="0 1 0 1"/>
			</material>
		</visual>
	</link>

	<link name ="roll_bar_2">
		<visual>
			<geometry>
				<cylinder length="0.07" radius="0.0065" />
			</geometry>
			<origin xyz="-0.035 0 0" rpy="1.570796 0 1.570796"/>
			<material name="roll"/>
		</visual>
	</link>	

	<link name ="pinch_bar_1">
		<visual>
			<geometry>
				<box size="0.05 0.02 0.002"/>
			</geometry>
			<origin xyz="0.025 0 0"/>
			<material name ="pinch">
				<color rgba="1 1 0 1"/>
			</material>
		</visual>
	</link>

	<joint name="pitch" type="continuous">
		<parent link="base_link"/>
		<child link="pitch_bar_1"/>
		<axis xyz="1 0 0"/>
		<origin xyz = "0 0 0.165"/>
	</joint>

	<joint name="pitch_1" type="fixed">
		<parent link="pitch_bar_1"/>
		<child link="pitch_bar_2"/>
		<axis xyz="1 0 0"/>
		<origin xyz = "0.05 0 0"/>
	</joint>

	<joint name="pitch_2" type="fixed">
		<parent link="pitch_bar_2"/>
		<child link="pitch_bar_3"/>
		<axis xyz="1 0 0"/>
		<origin xyz = "0 0 -0.075"/>
	</joint>	

	<joint name="yaw" type="continuous">
		<parent link="pitch_bar_3"/>
		<child link="yaw_bar_1"/>
		<axis xyz="0 0 1"/>
		<origin xyz = "0.095 0 0"/>
	</joint>

	<joint name="yaw_1" type="fixed">
		<parent link="yaw_bar_1"/>
		<child link="yaw_bar_2"/>
		<axis xyz="0 0 1"/>
		<origin xyz = "0 0 0.0175"/>
	</joint>	

	<joint name="yaw_2" type="fixed">
		<parent link="yaw_bar_2"/>
		<child link="yaw_bar_3"/>
		<axis xyz="0 0 1"/>
		<origin xyz = "0.05 0 0"/>
	</joint>

	<joint name="roll" type="continuous">
		<parent link="yaw_bar_3"/>
		<child link="roll_bar_1"/>
		<axis xyz="1 0 0"/>
		<origin xyz = "0 0 0.0575"/>
	</joint>

	<joint name="roll_1" type="fixed">
		<parent link="roll_bar_1"/>
		<child link="roll_bar_2"/>
		<axis xyz="1 0 0"/>
		<origin xyz = "-0.04 0 0"/>
	</joint>

	<joint name="pinch" type="continuous">
		<parent link="roll_bar_2"/>
		<child link="pinch_bar_1"/>
		<axis xyz="0 -1 0"/>
		<origin xyz = "-0.07 0 0"/>
	</joint>


</robot>
	

